Workbook
Name Options: 'Marks Sheet'!$M$6:$M$9

Sheet MCQ TEST SHEET
A1: www.ExcelDataPro.com
A2: MCQ Test Sheet
A3: PYTHON UNIT 6,7,8 MCQ TEST
A5: PREPARED BY - PROF MANISH PATEL
A6: Sr | B6: QUESTIONS | C6: A | D6: B | E6: C | F6: D | G6: Your Answer
A7: 1 | B7: Which option/s is/are a possible output of following code? import random SEL=random. randint (1, 3) ANIMAL = ["DEER", "Monkey", "COW", "Kangaroo"] for A in ANIMAL: for AA in range (0, SEL): print (A, end ="") print () | C7: DEERDEER MonkeysMonkey COWCOW KangarooKangaroo | D7: DEER DELHIMONKEY DELHIMONKEYCOW | E7: DEER MONKEY cow KANGAROO | F7: DEER Monkey COW Kangaroo
A8: 2 | B8: Which option/s is/are a possible output of following code? import random PICK=random.randint (1,3) CITY= ["DELHI", "MUMBAI", "CHENNAI", "KOLKATA"] for I in CITY: for J in range (0, PICK): print (I, end = "") print () | C8: DELHIDELHII MUMBAIMUMBAI CHENNAICHENNAI KOLKATAKOLKATA | D8: DELHI DELHIMUMBAI DELHIMUMBAICHENNAI | E8: DELHI MUMBAI CHENNAI KOLKATA | F8: DELHI MUMBAIMUMBAI KOLKATAKOLKATAKOLKATA
A9: 3 | B9: Which option is not a possible output of following code? import random def main(): p = "MY PROGRAM" i = 0 while p[i] != "R": l = random.randint(0,3) + 5 print (p[l],end ="_") i += 1 main() | C9: M_M_Y_P | D9: R_G_A_G | E9: G_G_R_O | F9: O_G_G_A
A10: 4 | B10: Which option is not a possible output of following code? x = 3 N = random.randint (1, x) for i in range (N): print (i, "#", i + 1) | C10: 0#1 1#2 2#3 | D10: 0#1 1#2 | E10: 0#1 1#2 2#3 3#4 | F10: 0#1
A11: 5 | B11: Which option/s is/are a possible output of following code? import random movie_list = ['The Jungle Book', 'Finding Nemo', 'Harry Potter', 'The Incredibles', 'Frozen'] movie1 = random.choice(movie_list) movie2 = random.choice(movie_list) print ( movie1 ," or " ,movie2) | C11: Finding Nemo or Harry Potter | D11: Harry Potter or Toy Story | E11: Frozen or The Jungle | F11: Toy Story or Spider Man
A12: 6 | B12: Which option/s is/are a possible output of following code? import random color_list = ["Pink", "Red", "Sky blue", "Yellow", "Green"] random.shuffle(color_list) print ( color_list ) | C12: [‘Sky Blue’, ‘Green’, ‘Yellow’, ‘Pink’, ‘Red’] | D12: [‘Blue’, ‘Green’, ‘Pink’, ’Brown’, ‘Red’, ‘Black’] | E12: [Yellow, Sky blue, Green, Pink, Red] | F12: (‘Yellow’, ‘Red’, ‘Sky blue’, ‘Green’, ‘Pink’)
A13: 7 | B13: Which option/s is/are not a possible output of following code? import random list=[14, 62, 30, 57, 91] str= ('Simply') print ( random.choice(list),"and" , random.choice(str) ) | C13: 57 and i | D13: 62 and S | E13: 20 and p | F13: 30 and m
A14: 8 | B14: Which option/s is/are a possible output of following code? import random N=3 PICKER = random.randint (1, N) COLOR = ["BLUE", "PINK", "GREEN", "RED"] for I in COLOR : for J in range (0, PICKER): print (I, end = " ") print () | C14: BLUE PINK GREEN RED | D14: BLUE BLUEPINK BLUEPINKGREEN BLUEPINKGREENRED | E14: PINK PINKGREEN GREENRED | F14: BLUEBLUE PINKPINK GREEENGREEN GREENGREEN
A15: 9 | B15: Which option/s is/are a possible output of following code? import random n1= random.randrange(1, 10, 2) n2= random.randrange(1, 10, 3) print (n1,"and",n2) | C15: 2 and 7 | D15: 3 and 4 | E15: 8 and 10 | F15: 8 and 9
A16: 10 | B16: To include the use of functions which are present in the random library, we must use the option: | C16: import random | D16: random.h | E16: import.random | F16: random.random
A17: 11 | B17: What will be the output of the following Python code? import random random.choice(2,3,4) | C17: An integer other than 2, 3 and 4 | D17: Either 2, 3 or 4 | E17: Error | F17: 3 only
A18: 12 | B18: What will be the output of the following Python code? import random random.choice([10.4, 56.99, 76]) | C18: Error | D18: Either 10.4, 56.99 or 76 | E18: Any number other than 10.4, 56.99 and 76 | F18: 56.99 only
... A22: 16 | B22: What will be the output of the following Python function, assuming that the random library has already been included? random.shuffle[1,2,24] | C22: Randomized list containing the same numbers in any order | D22: The same list, that is [1,2,24] | E22: A list containing any random numbers between 1 and 24 | F22: Error
A23: 17 | B23: What does random.seed(3) return? | C23: TRUE | D23: None | E23: 3 | F23: 1
A24: 18 | B24: Which is the only one of the following values the function random.randint(4) can return? | C24: 4 | D24: 3.4 | E24: error | F24: 5
A25: 19 | B25: Which of the following will not be returned by random.choice(“1 ,”)? | C25: 1 | D25: Space tab | E25: , | F25: none of these
A26: 20 | B26: Which of the following will never be displayed on executing print(random.choice({0: 1, 2: 3})) initially ? | C26: 0 | D26: 1 | E26: KeyError | F26: none of these
A27: 21 | B27: What does random.shuffle(x) do when x = [1, 2, 3]? | C27: error | D27: do nothing | E27: shuffle elements of list in place | F27: none of these
A28: 22 | B28: Which type of elements are accepted by random.shuffle()? | C28: strings | D28: list | E28: tuples | F28: integers
A29: 23 | B29: What is the range of values that random.random() can return? | C29: [0.0,1.0] | D29: (0.0,1.0] | E29: (0.0,1.0) | F29: [0.0,1.0)
A30: 24 | B30: In SimpleGUICS2Pygame, how many event handlers can be running at the same time? | C30: 1 | D30: 2 | E30: 3 | F30: 4
A31: 25 | B31: Which one is not a part of a frame? | C31: widget | D31: Control Area | E31: Status Area | F31: Canvas
A32: 26 | B32: Which of the following are valid calls to create_frame? | C32: f = simplegui.create_Frame("My Frame", 100, 100) | D32: f = simplegui.create_frames("My Frame", 100, 100) | E32: frame = simplegui.create_frame(100, 100, 100) | F32: frame = simplegui.create_frame("Testing", 200, 200, 300)
A33: 27 | B33: Which of the following are valid ways of making a canvas with a red background? | C33: import simplegui frame = simplegui.Create_frame("My Frame", 100, 100) frame.set_canvas_background("Red") frame.start() | D33: import simplegui frame = simplegui.create_frame("My Frame", 100, 100) frame.set_canvas_background("red") frame.start() | E33: import simplegui frame = simplegui.create_frame( 100, 100) frame.set_canvas_background("red") frame.start() | F33: import simplegui frame = simplegui.create_frame("My Frame", 100, 100) frame.set_canvas_background("blue") frame.start()
A34: 28 | B34: In the following code, what does the number 100 represent? my_button = frame.add_button("My Label", button_handler, 100) | C34: Width of the button in pixels. | D34: Width and height of the button in pixels. | E34: Height of the button in pixels. | F34: Position of the button in pixels.
A35: 29 | B35: How many control objects are allowed in a frame? | C35: 0 or more | D35: 1 or more | E35: 2 or more | F35: 3 or more
A36: 30 | B36: In SimpleGUI, one kind of object can be added to the control panel that doesn't allow any handler. Thus, this object can't respond to anything. What kind of object is that? | C36: button | D36: label | E36: canvas | F36: title
A37: 31 | B37: When you enter text into an input field and press enter, the text is passed to the input field's event handler. What is the data type of the text? | C37: integer | D37: char | E37: string | F37: bytes
A38: 32 | B38: When does the event handler for an input field get called? | C38: when you press enter | D38: when you press escape | E38: when you press run | F38: none of these
A39: 33 | B39: When a user pushes a button, what argument is passed to the event handler? | C39: strings | D39: No arguments | E39: Command | F39: Parameters
A40: 34 | B40: What does the draw handler parameter represent? | C40: canvas | D40: string | E40: widget | F40: panel
A41: 35 | B41: What typically calls an event handler? | C41: the code we write | D41: some code that we don't write which generates the event | E41: it generates automatically | F41: none of these
A42: 36 | B42: The game programming in python follows below given sequence in alphabetical order. What is the correct order of sequence? 1. Create frames 2. Define Classes 3. Define event handlers 4. Initialize global variables 5. Define helper functions 6. Register event handlers 7. Start frame and timers | C42: 1,2,3,4,5,6,7 | D42: 4,5,2,1,3,6,7 | E42: 4,5,2,6,3,1,7 | F42: 4,5,2,3,1,6,7
... A55: 49 | B55: Turn the following description into a program, and run it. 1. Create a 300-by-300 canvas. 2. Draw two circles with radius 20 and white lines of width 10. One is centered at (90,200) and one at (210,200). 3. Draw a red line of width 40 from (50,180) to (250,180). 4. Draw two red lines of width 5 from (55,170) to (90,120) and from (90,120) to (130,120). 5. Draw a red line of width 140 from (180,108) to (180,160). The resulting picture is a simple diagram of what? | C55: A computer | D55: A house | E55: A motorcycle | F55: An Automobile
A56: 50 | B56: When the following code is executed, how many times is timer_handler called? import SimpleGUICS2Pygame.simpleguics2pygame as simplegui def timer_handler(): ''' timer = simplegui.create_timer(10, timer_handler) timer.start() The body of timer_handler isn’t given, as it is irrelevant for this question. | C56: 0 — The code hasn’t been written correctly. | D56: 1 | E56: 10 | F56: Unlimited — It is called repeatedly until you stop the program.
...

Sheet After Exam Data Entry
A1: Enter all relevant data here only after you finish the examination.
A5: Q. No. | B5: Marks assigned to the question | C5: Negative Marking | D5: Correct Answer
A6: 1 | B6: 1 | D6: D
A7: 2 | B7: 1 | D7: C
A8: 3 | B8: 1 | D8: A
A9: 4 | B9: 1 | D9: C
A10: 5 | B10: 1 | D10: A
A11: 6 | B11: 1 | D11: D
A12: 7 | B12: 1 | D12: C
A13: 8 | B13: 1 | D13: A
A14: 9 | B14: 1 | D14: B
A15: 10 | B15: 1 | D15: A
A16: 11 | B16: 1 | D16: C
A17: 12 | B17: 1 | D17: B
... A80: 75 | B80: 1 | D80: A
A81: 76 | B81: 1
A82: 77 | B82: 1
A83: 78 | B83: 1
A84: 79 | B84: 1
A85: 80 | B85: 1
A86: 81 | B86: 1
A87: 82 | B87: 1
A88: 83 | B88: 1
A89: 84 | B89: 1
A90: 85 | B90: 1
A91: 86 | B91: 1
A92: 87 | B92: 1
... A123: 118 | B123: 1

Sheet Marks Sheet
A2: Class | B2: Div | C2: UNIT | D2: T. Marks | E2: YEAR | G2: Sub | H2: Exam
A3: SEM IV | B3: A5/A9 | C3: 6,7,8 | E3: 2023 | G3: PYTHON-2 | H3: QUIZ
B4: MCQ Test Mark Sheet
B5: Question Number | C5: Marks assigned to this question | D5: Negative Marking | E5: Answer by student | F5: Correct Answer | G5: Marks Obtained
B6: 1 | C6: =IF('After Exam Data Entry'!B6="", "", 'After Exam Data Entry'!B6) -> 1 | D6: =IF(C6="", "", IF('After Exam Data Entry'!C6="", 0, 'After Exam Data Entry'!C6)) -> 0 | E6: =IF('MCQ TEST SHEET'!G7="", "", 'MCQ TEST SHEET'!G7) | F6: =IF('After Exam Data Entry'!D6="", "", 'After Exam Data Entry'!D6) -> D | G6: =IF(F6="", "", IF(E6="", "", IF(E6=F6, C6, D6)))
B7: 2 | C7: =IF('After Exam Data Entry'!B7="", "", 'After Exam Data Entry'!B7) -> 1 | D7: =IF(C7="", "", IF('After Exam Data Entry'!C7="", 0, 'After Exam Data Entry'!C7)) -> 0 | E7: =IF('MCQ TEST SHEET'!G8="", "", 'MCQ TEST SHEET'!G8) | F7: =IF('After Exam Data Entry'!D7="", "", 'After Exam Data Entry'!D7) -> C | G7: =IF(F7="", "", IF(E7="", "", IF(E7=F7, C7, D7)))
B8: 3 | C8: =IF('After Exam Data Entry'!B8="", "", 'After Exam Data Entry'!B8) -> 1 | D8: =IF(C8="", "", IF('After Exam Data Entry'!C8="", 0, 'After Exam Data Entry'!C8)) -> 0 | E8: =IF('MCQ TEST SHEET'!G9="", "", 'MCQ TEST SHEET'!G9) | F8: =IF('After Exam Data Entry'!D8="", "", 'After Exam Data Entry'!D8) -> A | G8: =IF(F8="", "", IF(E8="", "", IF(E8=F8, C8, D8)))
B9: 4 | C9: =IF('After Exam Data Entry'!B9="", "", 'After Exam Data Entry'!B9) -> 1 | D9: =IF(C9="", "", IF('After Exam Data Entry'!C9="", 0, 'After Exam Data Entry'!C9)) -> 0 | E9: =IF('MCQ TEST SHEET'!G10="", "", 'MCQ TEST SHEET'!G10) | F9: =IF('After Exam Data Entry'!D9="", "", 'After Exam Data Entry'!D9) -> C | G9: =IF(F9="", "", IF(E9="", "", IF(E9=F9, C9, D9)))
B10: 5 | C10: =IF('After Exam Data Entry'!B10="", "", 'After Exam Data Entry'!B10) -> 1 | D10: =IF(C10="", "", IF('After Exam Data Entry'!C10="", 0, 'After Exam Data Entry'!C10)) -> 0 | E10: =IF('MCQ TEST SHEET'!G11="", "", 'MCQ TEST SHEET'!G11) | F10: =IF('After Exam Data Entry'!D10="", "", 'After Exam Data Entry'!D10) -> A | G10: =IF(F10="", "", IF(E10="", "", IF(E10=F10, C10, D10)))
B11: 6 | C11: =IF('After Exam Data Entry'!B11="", "", 'After Exam Data Entry'!B11) -> 1 | D11: =IF(C11="", "", IF('After Exam Data Entry'!C11="", 0, 'After Exam Data Entry'!C11)) -> 0 | E11: =IF('MCQ TEST SHEET'!G12="", "", 'MCQ TEST SHEET'!G12) | F11: =IF('After Exam Data Entry'!D11="", "", 'After Exam Data Entry'!D11) -> D | G11: =IF(F11="", "", IF(E11="", "", IF(E11=F11, C11, D11)))
B12: 7 | C12: =IF('After Exam Data Entry'!B12="", "", 'After Exam Data Entry'!B12) -> 1 | D12: =IF(C12="", "", IF('After Exam Data Entry'!C12="", 0, 'After Exam Data Entry'!C12)) -> 0 | E12: =IF('MCQ TEST SHEET'!G13="", "", 'MCQ TEST SHEET'!G13) | F12: =IF('After Exam Data Entry'!D12="", "", 'After Exam Data Entry'!D12) -> C | G12: =IF(F12="", "", IF(E12="", "", IF(E12=F12, C12, D12)))
B13: 8 | C13: =IF('After Exam Data Entry'!B13="", "", 'After Exam Data Entry'!B13) -> 1 | D13: =IF(C13="", "", IF('After Exam Data Entry'!C13="", 0, 'After Exam Data Entry'!C13)) -> 0 | E13: =IF('MCQ TEST SHEET'!G14="", "", 'MCQ TEST SHEET'!G14) | F13: =IF('After Exam Data Entry'!D13="", "", 'After Exam Data Entry'!D13) -> A | G13: =IF(F13="", "", IF(E13="", "", IF(E13=F13, C13, D13)))
B14: 9 | C14: =IF('After Exam Data Entry'!B14="", "", 'After Exam Data Entry'!B14) -> 1 | D14: =IF(C14="", "", IF('After Exam Data Entry'!C14="", 0, 'After Exam Data Entry'!C14)) -> 0 | E14: =IF('MCQ TEST SHEET'!G15="", "", 'MCQ TEST SHEET'!G15) | F14: =IF('After Exam Data Entry'!D14="", "", 'After Exam Data Entry'!D14) -> B | G14: =IF(F14="", "", IF(E14="", "", IF(E14=F14, C14, D14)))
B15: 10 | C15: =IF('After Exam Data Entry'!B15="", "", 'After Exam Data Entry'!B15) -> 1 | D15: =IF(C15="", "", IF('After Exam Data Entry'!C15="", 0, 'After Exam Data Entry'!C15)) -> 0 | E15: =IF('MCQ TEST SHEET'!G16="", "", 'MCQ TEST SHEET'!G16) | F15: =IF('After Exam Data Entry'!D15="", "", 'After Exam Data Entry'!D15) -> A | G15: =IF(F15="", "", IF(E15="", "", IF(E15=F15, C15, D15)))
B16: 11 | C16: =IF('After Exam Data Entry'!B16="", "", 'After Exam Data Entry'!B16) -> 1 | D16: =IF(C16="", "", IF('After Exam Data Entry'!C16="", 0, 'After Exam Data Entry'!C16)) -> 0 | E16: =IF('MCQ TEST SHEET'!G17="", "", 'MCQ TEST SHEET'!G17) | F16: =IF('After Exam Data Entry'!D16="", "", 'After Exam Data Entry'!D16) -> C | G16: =IF(F16="", "", IF(E16="", "", IF(E16=F16, C16, D16)))
B17: 12 | C17: =IF('After Exam Data Entry'!B17="", "", 'After Exam Data Entry'!B17) -> 1 | D17: =IF(C17="", "", IF('After Exam Data Entry'!C17="", 0, 'After Exam Data Entry'!C17)) -> 0 | E17: =IF('MCQ TEST SHEET'!G18="", "", 'MCQ TEST SHEET'!G18) | F17: =IF('After Exam Data Entry'!D17="", "", 'After Exam Data Entry'!D17) -> B | G17: =IF(F17="", "", IF(E17="", "", IF(E17=F17, C17, D17)))
... B80: 75 | C80: =IF('After Exam Data Entry'!B80="", "", 'After Exam Data Entry'!B80) -> 1 | D80: =IF(C80="", "", IF('After Exam Data Entry'!C80="", 0, 'After Exam Data Entry'!C80)) -> 0 | E80: =IF('MCQ TEST SHEET'!G81="", "", 'MCQ TEST SHEET'!G81) | F80: =IF('After Exam Data Entry'!D80="", "", 'After Exam Data Entry'!D80) -> A | G80: =IF(F80="", "", IF(E80="", "", IF(E80=F80, C80, D80)))
B82: TOTAL | C82: =SUM(C6:C81) -> 75 | E82: Marks Obtained | G82: =SUM(G6:G81) -> 0
B83: Result | C83: =IF(G83<33%, "Fail", "Pass") -> Fail | E83: % Obtained | G83: =(G82/C82) -> 0
B84: Grade Obtained | D84: =IFERROR(IF(C85="", "", IF(C85<=32%, "Needs Improvement", IF(C85<=50%, "P", IF(C85<=55%, "C", IF(C85<=60%, "B", IF(C85<=70%, "B+", IF(C85<=80%, "A", IF(C85<=90%, "A+", "A++" )))))))), "") -> Needs Improvement
C85: =G82/C82 -> 0
